Workbook

Sheet Exhibit 1
A1: 2025 Quarter 3 - Condensed Consolidated Statement of Income | D1: Quarter 2 | H1: Quarter 1
C2: Three Months Ended | E2: Nine Months Ended | G2: Three Months Ended | I2: Six Months Ended | K2: Three Months Ended
A3: (millions of dollars, unless noted) | C3: September 30, | E3: September 30, | G3: June 30, | I3: June 30, | K3: March 31,
B4: 2025 | C4: 2024 | D4: 2025 | E4: 2024 | F4: 2025 | G4: 2024 | H4: 2025 | I4: 2024 | J4: 2025 | K4: 2024
A5: Revenues and other income
A6: Sales and other operating revenue | B6: 83331 | C6: 87792 | D6: 243866 | E6: 258189 | F6: 79477 | G6: 89986 | H6: 160535 | I6: 170397 | J6: 81058 | K6: 80411
A7: Income from equity affiliates | B7: 1267 | C7: 1481 | D7: 4098 | E7: 5067 | F7: 1462 | G7: 1744 | H7: 2831 | I7: 3586 | J7: 1369 | K7: 1842
A8: Other income | B8: 696 | C8: 743 | D8: 1966 | E8: 2903 | F8: 567 | G8: 1330 | H8: 1270 | I8: 2160 | J8: 703 | K8: 830
A9: Total revenues and other income | B9: 85294 | C9: 90016 | D9: 249930 | E9: 266159 | F9: 81506 | G9: 93060 | H9: 164636 | I9: 176143 | J9: 83130 | K9: 83083
A10: Costs and other deductions
A11: Crude oil and product purchases | B11: 47928 | C11: 51261 | D11: 140043 | E11: 153061 | F11: 45327 | G11: 54199 | H11: 92115 | I11: 101800 | J11: 46788 | K11: 47601
A12: Production and manufacturing expenses | B12: 10094 | C12: 9881 | D12: 30279 | E12: 28776 | F12: 10102 | G12: 9804 | H12: 20185 | I12: 18895 | J12: 10083 | K12: 9091
A13: Selling, general and administrative expenses | B13: 3032 | C13: 2296 | D13: 8100 | E13: 7359 | F13: 2528 | G13: 2568 | H13: 5068 | I13: 5063 | J13: 2540 | K13: 2495
A14: Depreciation and depletion (includes impairments) | B14: 6475 | C14: 6258 | D14: 18278 | E14: 16857 | F14: 6101 | G14: 5787 | H14: 11803 | I14: 10599 | J14: 5702 | K14: 4812
A15: Exploration expenses, including dry holes | B15: 149 | C15: 339 | D15: 464 | E15: 640 | F15: 251 | G15: 153 | H15: 315 | I15: 301 | J15: 64 | K15: 148
A16: Non-service pension and postretirement benefit expense | B16: 119 | C16: 33 | D16: 322 | E16: 90 | F16: 90 | G16: 34 | H16: 203 | I16: 57 | J16: 113 | K16: 23
A17: Interest expense | B17: 90 | C17: 207 | D17: 440 | E17: 699 | F17: 145 | G17: 271 | H17: 250 | I17: 492 | J17: 205 | K17: 221
A18: Other taxes and duties | B18: 6475 | C18: 6715 | D18: 18767 | E18: 19617 | F18: 6257 | G18: 6579 | H18: 12292 | I18: 12902 | J18: 6035 | K18: 6323
A19: Total costs and other deductions | B19: 74362 | C19: 76990 | D19: 216693 | E19: 227099 | F19: 70801 | G19: 79395 | H19: 142331 | I19: 150109 | J19: 71530 | K19: 70714
A20: Income (loss) before income taxes | B20: 10932 | C20: 13026 | D20: 33237 | E20: 39060 | F20: 10705 | G20: 13665 | H20: 22305 | I20: 26034 | J20: 11600 | K20: 12369
A21: Income tax expense (benefit) | B21: 3164 | C21: 4055 | D21: 10082 | E21: 11952 | F21: 3351 | G21: 4094 | H21: 6918 | I21: 7897 | J21: 3567 | K21: 3803
A22: Net income (loss) including noncontrolling interests | B22: 7768 | C22: 8971 | D22: 23155 | E22: 27108 | F22: 7354 | G22: 9571 | H22: 15387 | I22: 18137 | J22: 8033 | K22: 8566
... A26: Earnings (loss) per common share - assuming dilution (dollars) | B26: 1.76 | C26: 1.92 | D26: 5.16 | E26: 6.12 | F26: 1.64 | G26: 2.14 | H26: 3.4 | I26: 4.2 | J26: 1.76 | K26: 2.06

Sheet Exhibit 2
A1: Condensed Consolidated Balance Sheet for Q1, Q2, Q3 in 2025
B2: Q3 | C2: Q2 | D2: Q1 | E2: 2024
A3: (millions of dollars, unless noted) | B3: 45930 | C3: 45838 | D3: 45747 | E3: 45657
A4: ASSETS
A5: Current assets
A6: Cash and cash equivalents | B6: 13814 | C6: 14352 | D6: 17036 | E6: 23029
A7: Cash and cash equivalents – restricted | B7: 55 | C7: 1359 | D7: 1476 | E7: 158
A8: Notes and accounts receivable – net | B8: 45285 | C8: 41792 | D8: 46303 | E8: 43681
A9: Inventories
A10: Crude oil, products and merchandise | B10: 23174 | C10: 21364 | D10: 20502 | E10: 19444
A11: Materials and supplies | B11: 4064 | C11: 4007 | D11: 3976 | E11: 4080
A12: Other current assets | B12: 2113 | C12: 2234 | D12: 1940 | E12: 1598
A13: Total current assets | B13: 88505 | C13: 85108 | D13: 91233 | E13: 91990
A14: Investments, advances and long-term receivables | B14: 46138 | C14: 46092 | D14: 47853 | E14: 47200
A15: Property, plant and equipment – net | B15: 298388 | C15: 295356 | D15: 292646 | E15: 294318
A16: Other assets, including intangibles – net | B16: 21309 | C16: 21041 | D16: 20176 | E16: 19967
A17: Total Assets | B17: 454340 | C17: 447597 | D17: 451908 | E17: 453475
A18: LIABILITIES
A19: Current liabilities
A20: Notes and loans payable | B20: 9212 | C20: 5419 | D20: 4728 | E20: 4955
A21: Accounts payable and accrued liabilities | B21: 65382 | C21: 59725 | D21: 63987 | E21: 61297
A22: Income taxes payable | B22: 3256 | C22: 3017 | D22: 5114 | E22: 4055
A23: Total current liabilities | B23: 77850 | C23: 68181 | D23: 73829 | E23: 70307
A24: Long-term debt | B24: 32824 | C24: 33570 | D24: 32823 | E24: 36755
A25: Postretirement benefits reserves | B25: 10394 | C25: 10352 | D25: 10015 | E25: 9700
A26: Deferred income tax liabilities | B26: 39942 | C26: 39368 | D26: 39091 | E26: 39042
A27: Long-term obligations to equity companies | B27: 1145 | C27: 1113 | D27: 1381 | E27: 1346
A28: Other long-term obligations | B28: 23962 | C28: 25071 | D28: 24963 | E28: 25719
A29: Total Liabilities | B29: 186117 | C29: 177635 | D29: 182102 | E29: 182869

Sheet Exhibit 3
A1: Condensed Consolidated Statement of Income
A3: (millions of dollars, unless noted)
B4: 2024 | C4: 2023 | D4: 2022 | E4: 2021 | F4: 2020 | G4: 2019 | H4: 2018 | I4: 2017 | J4: 2016 | K4: 2015
A5: Revenues and other income
A6: Sales and other operating revenue | B6: 339247 | C6: 334697 | D6: 398675 | E6: 276692 | F6: 178574 | G6: 225583 | H6: 279332 | I6: 237162 | J6: 218608 | K6: 259488
A7: Income from equity affiliates | B7: 6194 | C7: 6385 | D7: 11463 | E7: 6657 | F7: 1732 | G7: 5441 | H7: 7355 | I7: 5380 | J7: 4806 | K7: 7644
A8: Other income | B8: 4144 | C8: 3500 | D8: 3542 | E8: 2291 | F8: 1196 | G8: 3914 | H8: 3525 | I8: 1821 | J8: 2680 | K8: 1750
A9: Total revenues and other income | B9: 349585 | C9: 344582 | D9: 413680 | E9: 285640 | F9: 181502 | G9: 264938 | H9: 290212 | I9: 244363 | J9: 226094 | K9: 268882
A10: Costs and other deductions
A11: Crude oil and product purchases | B11: 199454 | C11: 193029 | D11: 228959 | E11: 155164 | F11: 94007 | G11: 143801 | H11: 156172 | I11: 128217 | J11: 104171 | K11: 130003
A12: Production and manufacturing expenses | B12: 39609 | C12: 36885 | D12: 42609 | E12: 36035 | F12: 30431 | G12: 36826 | H12: 36682 | I12: 32690 | J12: 31927 | K12: 35587
A13: Selling, general and administrative expenses | B13: 9976 | C13: 9919 | D13: 10095 | E13: 9574 | F13: 10168 | G13: 11398 | H13: 11480 | I13: 10649 | J13: 10799 | K13: 11501
A14: Depreciation and depletion (includes impairments) | B14: 23442 | C14: 20641 | D14: 24040 | E14: 20607 | F14: 46009 | G14: 18998 | H14: 18745 | I14: 19893 | J14: 22308 | K14: 18048
A15: Exploration expenses, including dry holes | B15: 826 | C15: 751 | D15: 1025 | E15: 1054 | F15: 1285 | G15: 1269 | H15: 1466 | I15: 1790 | J15: 1467 | K15: 1523
A16: Non-service pension and postretirement benefit expense | B16: 121 | C16: 714 | D16: 482 | E16: 786 | F16: 1205 | G16: 1235 | H16: 1285 | I16: 1745 | J16: 1835
A17: Interest expense | B17: 996 | C17: 849 | D17: 798 | E17: 947 | F17: 1158 | G17: 830 | H17: 766 | I17: 601 | J17: 453 | K17: 311
A18: Other taxes and duties | B18: 26288 | C18: 29011 | D18: 27919 | E18: 30239 | F18: 26122 | G18: 30525 | H18: 32663 | I18: 30104 | J18: 29020 | K18: 22678
A19: Total costs and other deductions | B19: 300712 | C19: 291799 | D19: 335927 | E19: 254406 | F19: 210385 | G19: 244882 | H19: 259259 | I19: 225689 | J19: 200145 | K19: 246916
A20: Income (loss) before income taxes | B20: 48873 | C20: 52783 | D20: 77753 | E20: 31234 | F20: -28883 | G20: 20056 | H20: 30953 | I20: 18674 | J20: 7969 | K20: 21966
A21: Income tax expense (benefit) | B21: 13810 | C21: 15429 | D21: 20176 | E21: 7636 | F21: -5632 | G21: 5282 | H21: 9532 | I21: -1174 | J21: -406 | K21: 5415
A22: Net income (loss) including noncontrolling interests | B22: 35063 | C22: 37354 | D22: 57577 | E22: 23598 | F22: -23251 | G22: 14774 | H22: 21421 | I22: 19848 | J22: 8375 | K22: 16551
A23: Net income (loss) attributable to noncontrolling interests | B23: 1383 | C23: 1344 | D23: 20176 | E23: 558 | F23: -811 | G23: 434 | H23: 581 | I23: 138 | J23: 535 | K23: 401
A24: Net income (loss) attributable to ExxonMobil | B24: 33680 | C24: 36010 | D24: 55740 | E24: 23040 | F24: -22440 | G24: 14340 | H24: 20840 | I24: 19710 | J24: 7840 | K24: 16150
A25: Earnings (loss) per common share (dollars) | B25: 7.84 | C25: 8.89 | D25: 13.26 | E25: 5.39 | F25: -5.25 | G25: 3.36 | H25: 4.88 | I25: 4.63 | J25: 1.88 | K25: 3.85
A26: Earnings (loss) per common share - assuming dilution (dollars) | B26: 7.84 | C26: 8.89 | D26: 13.26 | E26: 5.39 | F26: -5.25 | G26: 3.36 | H26: 4.88 | I26: 4.63 | J26: 1.88 | K26: 3.85

Sheet Exhibit 4
A1: Condensed Consolidated Balance Sheet
A3: (millions of dollars, unless noted) | B3: 2024 | C3: 2023 | D3: 2022 | E3: 2021 | F3: 2020 | G3: 2019 | H3: 2018 | I3: 2017 | J3: 2016 | K3: 2015
A4: ASSETS
A5: Current assets
A6: Cash and cash equivalents | B6: 23029 | C6: 31539 | D6: 29640 | E6: 6802 | F6: 4364 | G6: 3089 | H6: 3042 | I6: 3177 | J6: 3657 | K6: 3705
A7: Cash and cash equivalents – restricted | B7: 158 | C7: 29 | D7: 25 | E7: 0 | F7: 0 | G7: 0 | H7: 0 | I7: 0 | J7: 0 | K7: 0
A8: Notes and accounts receivable – net | B8: 43681 | C8: 38015 | D8: 41749 | E8: 32383 | F8: 20581 | G8: 26966 | H8: 24701 | I8: 25597 | J8: 21394 | K8: 19875
A9: Inventories
A10: Crude oil, products and merchandise | B10: 19444 | C10: 20528 | D10: 20434 | E10: 14519 | F10: 14169 | G10: 14010 | H10: 14803 | I10: 12871 | J10: 10877 | K10: 12037
A11: Materials and supplies | B11: 4080 | C11: 4592 | D11: 4001 | E11: 4261 | F11: 4681 | G11: 4518 | H11: 4155 | I11: 4121 | J11: 4203 | K11: 4208
A12: Other current assets | B12: 1598 | C12: 1906 | D12: 1782 | E12: 1189 | F12: 1098 | G12: 1469 | H12: 1272 | I12: 1368 | J12: 1285 | K12: 2798
A13: Total current assets | B13: 91990 | C13: 96609 | D13: 97631 | E13: 59154 | F13: 44893 | G13: 50052 | H13: 47973 | I13: 47134 | J13: 41416 | K13: 42623
A14: Investments, advances and long-term receivables | B14: 47200 | C14: 47630 | D14: 49793 | E14: 45195 | F14: 43515 | G14: 43164 | H14: 40790 | I14: 39160 | J14: 35102 | K14: 34245
A15: Property, plant and equipment – net | B15: 294318 | C15: 214940 | D15: 204692 | E15: 216552 | F15: 227553 | G15: 253018 | H15: 247101 | I15: 252630 | J15: 244224 | K15: 251605
A16: Other assets, including intangibles – net | B16: 19967 | C16: 17138 | D16: 16951 | E16: 18022 | F16: 16789 | G16: 16363 | H16: 10332 | I16: 9767 | J16: 9572 | K16: 8285
A17: Total Assets | B17: 453475 | C17: 376317 | D17: 369067 | E17: 338923 | F17: 332750 | G17: 362597 | H17: 346196 | I17: 348691 | J17: 330314 | K17: 336758
A18: LIABILITIES
A19: Current liabilities
A20: Notes and loans payable | B20: 4955 | C20: 4090 | D20: 634 | E20: 4276 | F20: 20458 | G20: 20578 | H20: 17258 | I20: 17930 | J20: 13830 | K20: 18762
A21: Accounts payable and accrued liabilities | B21: 61297 | C21: 58037 | D21: 63197 | E21: 50766 | F21: 35221 | G21: 41831 | H21: 37268 | I21: 36796 | J21: 31193 | K21: 32412
A22: Income taxes payable | B22: 4055 | C22: 3189 | D22: 5214 | E22: 1601 | F22: 684 | G22: 1580 | H22: 2612 | I22: 3045 | J22: 2615 | K22: 2802
A23: Total current liabilities | B23: 70307 | C23: 65316 | D23: 69045 | E23: 56643 | F23: 56363 | G23: 63989 | H23: 57138 | I23: 57771 | J23: 47638 | K23: 53976
A24: Long-term debt | B24: 36755 | C24: 37483 | D24: 40559 | E24: 43428 | F24: 47182 | G24: 26342 | H24: 20538 | I24: 24406 | J24: 28932 | K24: 19925
A25: Postretirement benefits reserves | B25: 9700 | C25: 10496 | D25: 10045 | E25: 18430 | F25: 22415 | G25: 22304 | H25: 20272 | I25: 21132 | J25: 20932 | K25: 22647
A26: Deferred income tax liabilities | B26: 39042 | C26: 24452 | D26: 22874 | E26: 20165 | F26: 18165 | G26: 25620 | H26: 27244 | I26: 26893 | J26: 34041 | K26: 36818
A27: Long-term obligations to equity companies | B27: 1346 | C27: 1804 | D27: 2338 | E27: 2857 | F27: 3253 | G27: 3988 | H27: 4382 | I27: 4774 | J27: 5124 | K27: 5417
A28: Other long-term obligations | B28: 25719 | C28: 24228 | D28: 21733 | E28: 21717 | F28: 21242 | G28: 21416 | H28: 18094 | I28: 19215 | J28: 20069 | K28: 21165
A29: Total Debt | B29: =B20+B24 -> 41710 | C29: =C20+C24 -> 41573 | D29: =D20+D24 -> 41193 | E29: =E20+E24 -> 47704 | F29: =F20+F24 -> 67640 | G29: =G20+G24 -> 46920 | H29: =H20+H24 -> 37796 | I29: =I20+I24 -> 42336 | ... K29: =K20+K24 -> 38687
A30: Total Liabilities | B30: 182869 | C30: 163779 | D30: 166594 | E30: 163240 | F30: 168620 | G30: 163659 | H30: 147668 | I30: 154191 | J30: 156484 | K30: 159948
A31: Commitments and contingencies
A32: EQUITY
A33: Common stock without par value
A34: (9,000 million shares authorized, 8,019 million shares issued) | B34: 46238 | C34: 17781 | D34: 15752 | E34: 15746 | F34: 15688 | G34: 15637 | H34: 15258 | I34: 14656 | J34: 12157 | K34: 11612
A35: Earnings reinvested | B35: 470903 | C35: 453927 | D35: 432860 | E35: 392059 | F35: 383943 | G35: 421341 | H35: 421653 | I35: 414540 | J35: 407831 | K35: 412444
A36: Accumulated other comprehensive income | B36: -14619 | C36: -11989 | D36: -13270 | E36: -13764 | F36: -16705 | G36: -19493 | H36: -19564 | I36: -16262 | J36: -22239 | K36: -23517
A37: Common stock held in treasury
A38: (3,666 million shares in 2024 and 4,048 million shares in 2023) | B38: -238817 | C38: -254917 | D38: -240293 | E38: -225464 | F38: -225776 | G38: -225835 | H38: -225553 | I38: -225246 | J38: -230424 | K38: -229734
A39: ExxonMobil share of equity | B39: 263705 | C39: 204802 | D39: 195049 | E39: 168577 | F39: 157150 | G39: 191650 | H39: 191794 | I39: 187688 | J39: 167325 | K39: 170817
A40: Noncontrolling interests | B40: 6901 | C40: 7736 | D40: 7424 | E40: 7106 | F40: 6980 | G40: 7288 | H40: 6734 | I40: 6812 | J40: 6505 | K40: 5999
A41: Total Equity | B41: 270606 | C41: 212538 | D41: 202473 | E41: 175683 | F41: 164130 | G41: 198938 | H41: 198528 | I41: 194500 | J41: 173830 | K41: 176810
...

Sheet Exhibit 5
A1: Condensed Consolidated Cash Flow Statement
A3: (millions of dollars, unless noted) | B3: 2024 | C3: 2023 | D3: 2022 | E3: 2021 | F3: 2020 | G3: 2019 | H3: 2018 | I3: 2017 | J3: 2016 | K3: 2015
A4: CASH FLOWS FROM OPERATING ACTIVITIES
A5: Net income (loss) including noncontrolling interests | B5: 35063 | C5: 37354 | D5: 57577 | E5: 23598 | F5: -23251 | G5: 14774 | H5: 21421 | I5: 19848 | J5: 8375 | K5: 16551
A6: Adjustments for noncash transactions
A7: Depreciation and depletion (includes impairments) | B7: 23422 | C7: 20641 | D7: 24040 | E7: 20607 | F7: 46009 | G7: 18998 | H7: 18745 | I7: 19893 | J7: 22308 | K7: 18048
A8: Deferred income tax charges/(credits) | B8: -865 | C8: 634 | D8: 3758 | E8: 303 | F8: -8856 | G8: -944 | H8: -60 | I8: -8577 | J8: -4386 | K8: -1832
A9: Postretirement benefits expense in excess of/(less than) net payments | B9: -358 | C9: 90 | D9: -2981 | E9: 754 | F9: 498 | G9: 109 | H9: 1070 | I9: 1135 | J9: -329 | K9: 2153
A10: Other long-term obligation provisions in excess of/(less than) payments | B10: -1712 | C10: -1501 | D10: -1932 | E10: 50 | F10: -1269 | G10: -3038 | H10: -68 | I10: -610 | J10: -19 | K10: -380
A11: Dividends received greater than/(less than) equity in current earnings of equity companies | B11: 191 | C11: 509 | D11: -2446 | E11: -668 | F11: 979 | G11: -936 | H11: -1684 | I11: 131 | J11: -579 | K11: -691
A12: Changes in operational working capital, excluding cash and debt
A13: Notes and accounts receivable reduction/(increase) | B13: -6030 | C13: 4370 | D13: -11019 | E13: -12098 | F13: 5384 | G13: -2640 | H13: -545 | I13: -3954 | J13: -2090 | K13: 4692
A14: Inventories reduction/(increase) | B14: -1812 | C14: -3472 | D14: -6947 | E14: -489 | F14: -315 | G14: 72 | H14: -3107 | I14: -1682 | J14: -388 | K14: -379
A15: Other current assets reduction/(increase) | B15: 389 | C15: -426 | D15: -688 | E15: -71 | F15: 420 | G15: -234 | H15: -25 | I15: -117 | J15: 171 | K15: 45
A16: Accounts and other payables increase/(reduction) | B16: 5627 | C16: -4727 | D16: 18460 | E16: 16820 | F16: -7142 | G16: 3725 | H16: 2321 | I16: 5104 | J16: 915 | K16: -7471
A17: Net (gain)/loss on asset sales | B17: -1223 | C17: -513 | D17: -1034 | E17: -1207 | F17: 4 | G17: -1710 | H17: -1993 | I17: -334 | J17: -1682 | K17: -226
A18: All other items - net | B18: 2310 | C18: 2410 | D18: 9 | E18: 530 | F18: 2207 | G18: 1540 | H18: -61 | I18: -771 | J18: -214 | K18: -166
A19: Net cash provided by operating activities | B19: 55022 | C19: 55369 | D19: 76797 | E19: 48129 | F19: 14668 | G19: 29716 | H19: 36014 | I19: 30066 | J19: 22082 | K19: 30344
A20: CASH FLOWS FROM INVESTING ACTIVITIES
A21: Additions to property, plant and equipment | B21: -24306 | C21: -21919 | D21: -18407 | E21: -12076 | F21: -17282 | G21: -24361 | H21: -19574 | I21: -15402 | J21: -16163 | K21: -26490
A22: Proceeds from asset sales and returns of investments | B22: 4987 | C22: 4078 | D22: 5247 | E22: 3176 | F22: 999 | G22: 3692 | H22: 4123 | I22: 3103 | J22: 4275 | K22: 2389
A23: Decrease/(increase) in restricted cash and cash equivalents | B23: 0 | C23: 0 | D23: 0 | E23: 0 | F23: 0 | G23: 0 | H23: 0 | I23: 0 | J23: 0 | K23: 42
A24: Additional investments and advances | B24: -3299 | C24: -2995 | D24: -3090 | E24: -2817 | F24: -4857 | G24: -3905 | H24: -1981 | I24: -5507 | J24: -1417 | K24: -607
A25: Other investing activities including collection of advances | B25: 1926 | C25: 1562 | D25: 1508 | E25: 1482 | F25: 2681 | G25: 1490 | H25: 986 | I25: 2076 | J25: 902 | K25: 842
A26: Cash acquired from mergers and acquisitions | B26: 754 | C26: 0 | D26: 0 | E26: 0 | F26: 0 | G26: 0 | H26: 0 | I26: 0 | J26: 0 | K26: 0
A27: Net cash used in investing activities | B27: -19938 | C27: -19274 | D27: -14742 | E27: -10235 | F27: -18459 | G27: -23084 | H27: -16446 | I27: -15730 | J27: -12403 | K27: -23824
A28: CASH FLOWS FROM FINANCING ACTIVITIES
A29: Additions to long-term debt | B29: 899 | C29: 939 | D29: 637 | E29: 46 | F29: 23186 | G29: 7052 | H29: 46 | I29: 60 | J29: 12066 | K29: 8028
A30: Reductions in long-term debt | B30: -1150 | C30: -15 | D30: -5 | E30: -8 | F30: -8 | G30: -1 | H30: 0 | I30: 0 | J30: 0 | K30: -26
A31: Additions to short-term debt | B31: - | C31: - | D31: 198 | E31: 12687 | F31: 35396 | G31: 18967 | H31: 0 | I31: 1735 | J31: 0 | K31: 0
A32: Reductions in short-term debt | B32: -4743 | C32: -879 | D32: -8075 | E32: -29396 | F32: -28742 | G32: -18367 | H32: -4752 | I32: -5024 | J32: -314 | K32: -506
A33: Additions/(reductions) in debt with three months or less maturity | B33: -18 | C33: -284 | D33: 25 | E33: -2983 | F33: -9691 | G33: 1011 | H33: -219 | I33: 2181 | J33: -7459 | K33: 1759
A34: Contingent consideration payments | B34: -27 | C34: -68 | D34: -58 | E34: -30 | F34: -21 | G34: - | H34: 0 | I34: 0 | J34: 0 | K34: 0
A35: Cash dividends to ExxonMobil shareholders | B35: -16704 | C35: -14941 | D35: -14939 | E35: -14924 | F35: -14865 | G35: -14652 | H35: -13798 | I35: -13001 | J35: -12453 | K35: -12090
A36: Cash dividends to noncontrolling interests | B36: -658 | C36: -531 | D36: -267 | E36: -224 | F36: -188 | G36: -192 | H36: -243 | I36: -184 | J36: -162 | K36: -170
A37: Changes in noncontrolling interests | B37: -791 | C37: -894 | D37: -1493 | E37: -436 | F37: 623 | G37: 158 | H37: 146 | I37: -150 | J37: 0 | K37: 2
A38: Inflows from noncontrolling interests for major projects | B38: 32 | C38: 124 | D38: 18 | E38: - | F38: - | G38: - | H38: 0 | I38: 0 | J38: 0 | K38: 0
A39: Common stock acquired | B39: -19629 | C39: -17748 | D39: -15155 | E39: -155 | F39: -405 | G39: -594 | H39: -626 | I39: -747 | J39: -977 | K39: 4039
A40: Common stock sold | B40: 0 | C40: 0 | D40: 0 | E40: 0 | F40: 0 | G40: 0 | H40: 0 | I40: 0 | J40: 6 | K40: 5
A41: Net cash provided by (used in) financing activities | B41: -42789 | C41: -34297 | D41: -39114 | E41: -35423 | F41: 5285 | G41: -6618 | H41: -19446 | I41: -15130 | J41: -9293 | K41: -7037
...

Sheet 10K
A1: Given Info (10-K)
A2: Income Statement
B3: 2014 | C3: 2015 | D3: 2016 | E3: 2017 | F3: 2018 | G3: 2019 | H3: 2020 | I3: 2021 | J3: 2022 | K3: 2023 | L3: 2024
A4: Revenue | B4: 367647 | C4: 239854 | D4: 200628 | E4: 237162 | F4: 279332 | G4: 255583 | H4: 178574 | I4: 276692 | J4: 398675 | K4: 334697 | L4: 339247
A5: Income Before Tax | B5: 51630 | C5: 21966 | D5: 7969 | E5: 18674 | F5: 30953 | G5: 20056 | H5: -28883 | I5: 31324 | J5: 77753 | K5: 52783 | L5: 48873
A6: Interest Expense | B6: 286 | C6: 311 | D6: 453 | E6: 601 | F6: 766 | G6: 830 | H6: 1158 | I6: 947 | J6: 798 | K6: 849 | L6: 996
A7: EBIT | B7: 51916 | C7: 22277 | D7: 8422 | E7: 19275 | F7: 31719 | G7: 20886 | H7: -27725 | I7: 32271 | J7: 78551 | K7: 53632 | L7: 49869
A8: Depreciation and Depletion | B8: 17297 | C8: 18048 | D8: 22308 | E8: 19893 | F8: 18745 | G8: 18998 | H8: 46009 | I8: 20607 | J8: 24040 | K8: 20461 | L8: 23442
A9: Income Tax Expense | B9: 18015 | C9: 5415 | D9: -406 | E9: -1174 | F9: 9532 | G9: 5282 | H9: -5632 | I9: 7636 | J9: 20176 | K9: 15429 | L9: 13810
A10: Effective Tax Rate | B10: 0.35 | C10: 0.25 | D10: -0.05 | E10: -0.06 | F10: 0.31 | G10: 0.26 | H10: 0.19 | I10: 0.24 | J10: 0.26 | K10: 0.29 | L10: 0.28
A11: EBIT Margin | B11: 0.14 | C11: 0.09 | D11: 0.04 | E11: 0.08 | F11: 0.11 | G11: 0.08 | H11: -0.16 | I11: 0.12 | J11: 0.2 | K11: 0.16 | L11: 0.15
A12: Balance Sheet
A13: CapEx | B13: -32952 | C13: -26490 | D13: -16163 | E13: -15402 | F13: -19574 | G13: 24361 | H13: -17282 | I13: -12076 | J13: -18407 | K13: -21919 | L13: -24306
A14: Change in NWC | B14: -4932 | C14: -3113 | D14: -182 | E14: -649 | F14: -2566 | G14: 923 | H14: -1653 | I14: 4162 | J14: -19688 | K14: -41 | L14: -8676
A15: Notes and AR | B15: 3118 | C15: 4692 | D15: -2090 | E15: -3954 | F15: -545 | G15: -2640 | H15: 5384 | I15: -12098 | J15: -11019 | K15: 4370 | L15: -6030
A16: Inventories | B16: -1343 | C16: -379 | D16: -388 | E16: -1682 | F16: -3107 | G16: 72 | H16: -315 | I16: -489 | J16: -6947 | K16: -3472 | L16: -1812
A17: Other assets | B17: -68 | C17: 45 | D17: -25 | E17: -117 | F17: 171 | G17: -234 | H17: 420 | I17: -71 | J17: -688 | K17: -426 | L17: 389
A18: Accounts and payables | B18: -6639 | C18: -7471 | D18: 2321 | E18: 5104 | F18: 915 | G18: 3725 | H18: -7142 | I18: 16820 | J18: -1034 | K18: -513 | L18: -1223
A20: Change NWC / Revenue | B20: 0.0134 | C20: 0.013 | D20: 0.0009 | E20: 0.0027 | F20: 0.0092 | G20: 0.0036 | H20: 0.0093 | I20: -0.015 | J20: 0.0494 | K20: 0.0001 | L20: 0.0256

Sheet DCF
A1: Historical FCFF | N1: Forecasted FCFF | Z1: WACC
B2: 2014 | C2: 2015 | D2: 2016 | E2: 2017 | F2: 2018 | G2: 2019 | H2: 2020 | I2: 2021 | J2: 2022 | K2: 2023 | L2: 2024 | N2: 2025 | O2: 2026 | P2: 2027 | Q2: 2028 | R2: 2029 | S2: 2030 | T2: 2031 | U2: 2032 | V2: 2033 | W2: 2034 | X2: 2035 | Z2: Market Value of Equity | AA2: ='Exhibit 4'!B47 -> 655910.04
A3: Revenue | B3: ='10K'!B4 -> 367647 | C3: ='10K'!C4 -> 239854 | D3: ='10K'!D4 -> 200628 | E3: ='10K'!E4 -> 237162 | F3: ='10K'!F4 -> 279332 | G3: ='10K'!G4 -> 255583 | H3: ='10K'!H4 -> 178574 | I3: ='10K'!I4 -> 276692 | ... L3: ='10K'!L4 -> 339247 | N3: =L3*(1+$L$6) -> 346299.99 | O3: =N3*(1+$L$6) -> 353499.61 | P3: =O3*(1+$L$6) -> 360848.91 | Q3: =P3*(1+$L$6) -> 368351 | R3: =Q3*(1+$L$6) -> 376009.06 | S3: =R3*(1+$L$6) -> 383826.34 | T3: =S3*(1+$L$6) -> 391806.14 | U3: =T3*(1+$L$6) -> 399951.83 | V3: =U3*(1+$L$6) -> 408266.88 | ... X3: =W3*(1+$L$6) -> 425419.19 | Z3: Total Debt | AA3: ='Exhibit 4'!B29 -> 41710 | AD3: Beta | AE3: Intrinsic price | AH3: WACC / Terminal growth | AI3: 0.02 | AJ3: 0.025 | AK3: 0.03
A4: Revenue Growth | C4: =(C3-B3)/B3 -> -0.34759702 | D4: =(D3-C3)/C3 -> -0.16354115 | E4: =(E3-D3)/D3 -> 0.18209821 | F4: =(F3-E3)/E3 -> 0.17781095 | G4: =(G3-F3)/F3 -> -0.085020692 | H4: =(H3-G3)/G3 -> -0.30130721 | I4: =(I3-H3)/H3 -> 0.54945289 | J4: =(J3-I3)/I3 -> 0.44086204 | ... L4: =(L3-K3)/K3 -> 0.013594385 | N4: =$L$6 -> 0.020790124 | O4: =$L$6 -> 0.020790124 | P4: =$L$6 -> 0.020790124 | Q4: =$L$6 -> 0.020790124 | R4: =$L$6 -> 0.020790124 | S4: =$L$6 -> 0.020790124 | T4: =$L$6 -> 0.020790124 | U4: =$L$6 -> 0.020790124 | ... X4: =$L$6 -> 0.020790124 | Z4: W(E) | AA4: =AA2/(AA2+AA3) -> 0.94021101 | AD4: 0.3 | AE4: 148.56412 | AH4: 0.055 | AI4: 147.08554 | AJ4: 165.11327 | AK4: 190.3521
A5: Pre-Tax Income | B5: ='10K'!B5 -> 51630 | C5: ='10K'!C5 -> 21966 | D5: ='10K'!D5 -> 7969 | E5: ='10K'!E5 -> 18674 | F5: ='10K'!F5 -> 30953 | G5: ='10K'!G5 -> 20056 | H5: ='10K'!H5 -> -28883 | I5: ='10K'!I5 -> 31324 | ... L5: ='10K'!L5 -> 48873 | Z5: W(D) | AA5: =AA3/(AA2+AA3) -> 0.059788993 | AD5: 0.36 | AE5: 136.40074 | AH5: 0.0578 | AI5: 136.23198 | AJ5: 151.13949 | AK5: 171.4094
A6: Average Growth Rate (without 2020 and 2022) | L6: =AVERAGE(C4:G4,I4,K4:L4) -> 0.020790124 | Z6: Beta | AA6: 0.36 | AD6: 0.4 | AE6: 129.34495 | AH6: 0.06 | AI6: 128.77029 | AJ6: 141.72781 | AK6: 159.00449
A7: EBIT | B7: ='10K'!B7 -> 51916 | C7: ='10K'!C7 -> 22277 | D7: ='10K'!D7 -> 8422 | E7: ='10K'!E7 -> 19275 | F7: ='10K'!F7 -> 31719 | G7: ='10K'!G7 -> 20886 | H7: ='10K'!H7 -> -27725 | I7: ='10K'!I7 -> 32271 | ... L7: ='10K'!L7 -> 49869 | N7: =N3*N8 -> 37323.443 | O7: =O3*O8 -> 38099.402 | P7: =P3*P8 -> 38891.493 | Q7: =Q3*Q8 -> 39700.052 | R7: =R3*R8 -> 40525.421 | S7: =S3*S8 -> 41367.95 | T7: =T3*T8 -> 42227.995 | U7: =U3*U8 -> 43105.92 | ... X7: =X3*X8 -> 45850.734 | Z7: MRP | AA7: 0.055 | AD7: 0.5 | AE7: 114.54417 | AH7: 0.065 | AI7: 114.52559 | AJ7: 124.18574 | AK7: 136.60592
A8: EBIT Margin | B8: ='10K'!B11 -> 0.14 | C8: ='10K'!C11 -> 0.09 | D8: ='10K'!D11 -> 0.04 | E8: ='10K'!E11 -> 0.08 | F8: ='10K'!F11 -> 0.11 | G8: ='10K'!G11 -> 0.08 | H8: ='10K'!H11 -> -0.16 | I8: ='10K'!I11 -> 0.12 | ... L8: ='10K'!L11 -> 0.15 | N8: =$L$9 -> 0.10777778 | O8: =$L$9 -> 0.10777778 | P8: =$L$9 -> 0.10777778 | Q8: =$L$9 -> 0.10777778 | R8: =$L$9 -> 0.10777778 | S8: =$L$9 -> 0.10777778 | T8: =$L$9 -> 0.10777778 | U8: =$L$9 -> 0.10777778 | ... X8: =$L$9 -> 0.10777778 | Z8: Risk Free Rate | AA8: 0.0405
A9: Average EBIT Margin (without 2020 and 2022) | L9: =AVERAGE(B8:G8,I8,K8:L8) -> 0.10777778 | Z9: Cost of Equity | AA9: =AA8+AA6*AA7 -> 0.0603
A10: Tax Expense | B10: ='10K'!B9 -> 18015 | C10: ='10K'!C9 -> 5415 | D10: ='10K'!D9 -> -406 | E10: ='10K'!E9 -> -1174 | F10: ='10K'!F9 -> 9532 | G10: ='10K'!G9 -> 5282 | H10: ='10K'!H9 -> -5632 | I10: ='10K'!I9 -> 7636 | ... L10: ='10K'!L9 -> 13810 | N10: =N7*N11 -> 9656.785 | O10: =O7*O11 -> 9857.5507 | P10: =P7*P11 -> 10062.49 | Q10: =Q7*Q11 -> 10271.691 | R10: =R7*R11 -> 10485.241 | S10: =S7*S11 -> 10703.23 | T10: =T7*T11 -> 10925.752 | U10: =U7*U11 -> 11152.899 | ... X10: =X7*X11 -> 11863.072 | Z10: Interest Expense | AA10: ='10K'!L6 -> 996
A11: Tax Rate | B11: ='10K'!B10 -> 0.35 | C11: ='10K'!C10 -> 0.25 | D11: ='10K'!D10 -> -0.05 | E11: ='10K'!E10 -> -0.06 | F11: ='10K'!F10 -> 0.31 | G11: ='10K'!G10 -> 0.26 | H11: ='10K'!H10 -> 0.19 | I11: ='10K'!I10 -> 0.24 | ... L11: ='10K'!L10 -> 0.28 | N11: =$L$12 -> 0.25873243 | O11: =$L$12 -> 0.25873243 | P11: =$L$12 -> 0.25873243 | Q11: =$L$12 -> 0.25873243 | R11: =$L$12 -> 0.25873243 | S11: =$L$12 -> 0.25873243 | T11: =$L$12 -> 0.25873243 | U11: =$L$12 -> 0.25873243 | ... X11: =$L$12 -> 0.25873243 | Z11: Cost of Debt | AA11: =AA10/AA3 -> 0.023879166
A12: Average Tax Rate (without 2020 and 2022) | L12: =SUM(B10:G10,I10,K10:L10)/SUM(B5:G5,I5,K5:L5) -> 0.25873243 | Z12: Tax Rate | AA12: =L12 -> 0.25873243
A13: NOPAT | B13: =B7*(1-B11) -> 33745.4 | C13: =C7*(1-C11) -> 16707.75 | D13: =D7*(1-D11) -> 8843.1 | E13: =E7*(1-E11) -> 20431.5 | F13: =F7*(1-F11) -> 21886.11 | G13: =G7*(1-G11) -> 15455.64 | H13: =H7*(1-H11) -> -22457.25 | I13: =I7*(1-I11) -> 24525.96 | ... L13: =L7*(1-L11) -> 35905.68 | N13: =N7*(1-N11) -> 27666.658 | O13: =O7*(1-O11) -> 28241.851 | P13: =P7*(1-P11) -> 28829.003 | Q13: =Q7*(1-Q11) -> 29428.361 | R13: =R7*(1-R11) -> 30040.181 | S13: =S7*(1-S11) -> 30664.72 | T13: =T7*(1-T11) -> 31302.243 | U13: =U7*(1-U11) -> 31953.021 | ... X13: =X7*(1-X11) -> 33987.663 | Z13: After-Tax Cost of Debt | AA13: =AA11*(1-AA12) -> 0.017700851
A14: Invested Capital | C14: ='Exhibit 4'!K29+'Exhibit 4'!K41-'Exhibit 4'!K6 -> 211792 | D14: ='Exhibit 4'!J29+'Exhibit 4'!J41-'Exhibit 4'!J6 -> 212935 | E14: ='Exhibit 4'!I29+'Exhibit 4'!I41-'Exhibit 4'!I6 -> 233659 | F14: ='Exhibit 4'!H29+'Exhibit 4'!H41-'Exhibit 4'!H6 -> 233282 | G14: ='Exhibit 4'!G29+'Exhibit 4'!G41-'Exhibit 4'!G6 -> 242769 | H14: ='Exhibit 4'!F29+'Exhibit 4'!F41-'Exhibit 4'!F6 -> 227406 | I14: ='Exhibit 4'!E29+'Exhibit 4'!E41-'Exhibit 4'!E6 -> 216585 | J14: ='Exhibit 4'!D29+'Exhibit 4'!D41-'Exhibit 4'!D6 -> 214026 | K14: ='Exhibit 4'!C29+'Exhibit 4'!C41-'Exhibit 4'!C6 -> 222572 | L14: ='Exhibit 4'!B29+'Exhibit 4'!B41-'Exhibit 4'!B6 -> 289287 | Z14: Terminal Growth Rate | AA14: 0.02
A15: ROIC | C15: =C13/C14 -> 0.078887541 | D15: =D13/D14 -> 0.041529575 | E15: =E13/E14 -> 0.087441528 | F15: =F13/F14 -> 0.093818254 | G15: =G13/G14 -> 0.063663977 | H15: =H13/H14 -> -0.098753991 | I15: =I13/I14 -> 0.11323942 | J15: =J13/J14 -> 0.27159196 | ... L15: =L13/L14 -> 0.12411785 | N15: =$L$16 -> 0.096722887 | O15: =$L$16 -> 0.096722887 | P15: =$L$16 -> 0.096722887 | Q15: =$L$16 -> 0.096722887 | R15: =$L$16 -> 0.096722887 | S15: =$L$16 -> 0.096722887 | T15: =$L$16 -> 0.096722887 | U15: =$L$16 -> 0.096722887 | ... X15: =$L$16 -> 0.096722887 | Z15: WACC | AA15: =AA4*AA9+AA5*AA13 -> 0.05775304
A16: Average ROIC (without 2020 and 2022) | L16: =AVERAGE(C15:G15,I15,K15:L15) -> 0.096722887
A17: Reinvestment | B17: =B21-B18+B24 -> 10723 | C17: =C21-C18+C24 -> 5329 | D17: =D21-D18+D24 -> -6327 | E17: =E21-E18+E24 -> -5140 | F17: =F21-F18+F24 -> -1737 | G17: =G21-G18+G24 -> -42436 | H17: =H21-H18+H24 -> -30380 | I17: =I21-I18+I24 -> -4369 | ... L17: =L21-L18+L24 -> -7812 | N17: =N4/N15*N13 -> 5946.8164 | O17: =O4/O15*O13 -> 6070.4515 | P17: =P4/P15*P13 -> 6196.6569 | Q17: =Q4/Q15*Q13 -> 6325.4862 | R17: =R4/R15*R13 -> 6456.9938 | S17: =S4/S15*S13 -> 6591.2355 | T17: =T4/T15*T13 -> 6728.2681 | U17: =U4/U15*U13 -> 6868.1496 | ... X17: =X4/X15*X13 -> 7305.4863
A18: D&A | B18: ='10K'!B8 -> 17297 | C18: ='10K'!C8 -> 18048 | D18: ='10K'!D8 -> 22308 | E18: ='10K'!E8 -> 19893 | F18: ='10K'!F8 -> 18745 | G18: ='10K'!G8 -> 18998 | H18: ='10K'!H8 -> 46009 | I18: ='10K'!I8 -> 20607 | ... L18: ='10K'!L8 -> 23442 | N18: =N3*N19 -> 25530.455 | O18: =O3*O19 -> 26061.237 | P18: =P3*P19 -> 26603.053 | Q18: =Q3*Q19 -> 27156.134 | R18: =R3*R19 -> 27720.713 | S18: =S3*S19 -> 28297.03 | T18: =T3*T19 -> 28885.329 | U18: =U3*U19 -> 29485.859 | ... X18: =X3*X19 -> 31363.401
A19: D&A (% of Revenue) | B19: =B18/B3 -> 0.047047848 | C19: =C18/C3 -> 0.075245775 | D19: =D18/D3 -> 0.11119086 | E19: =E18/E3 -> 0.083879374 | F19: =F18/F3 -> 0.067106526 | G19: =G18/G3 -> 0.074332017 | H19: =H18/H3 -> 0.25764669 | I19: =I18/I3 -> 0.074476313 | ... L19: =L18/L3 -> 0.069100095 | N19: =$L$20 -> 0.073723524 | O19: =$L$20 -> 0.073723524 | P19: =$L$20 -> 0.073723524 | Q19: =$L$20 -> 0.073723524 | R19: =$L$20 -> 0.073723524 | S19: =$L$20 -> 0.073723524 | T19: =$L$20 -> 0.073723524 | U19: =$L$20 -> 0.073723524 | ... X19: =$L$20 -> 0.073723524
A20: Average D&A (without 2020 and 2022) | L20: =AVERAGE(B19:G19,I19,K19:L19) -> 0.073723524
A21: CapEx | B21: =-'10K'!B13 -> 32952 | C21: =-'10K'!C13 -> 26490 | D21: =-'10K'!D13 -> 16163 | E21: =-'10K'!E13 -> 15402 | F21: =-'10K'!F13 -> 19574 | G21: =-'10K'!G13 -> -24361 | H21: =-'10K'!H13 -> 17282 | I21: =-'10K'!I13 -> 12076 | ... L21: =-'10K'!L13 -> 24306 | N21: =N17+N18-N24 -> 29418.711 | O21: =O17+O18-O24 -> 30030.329 | P21: =P17+P18-P24 -> 30654.664 | Q21: =Q17+Q18-Q24 -> 31291.978 | R21: =R17+R18-R24 -> 31942.542 | S21: =S17+S18-S24 -> 32606.631 | T21: =T17+T18-T24 -> 33284.527 | U21: =U17+U18-U24 -> 33976.517 | ... X21: =X17+X18-X24 -> 36140.007
A22: CapEx (% of Revenue, without 2020 and 2022) | B22: =B21/B3 -> 0.089629454 | C22: =C21/C3 -> 0.11044219 | D22: =D21/D3 -> 0.080562035 | E22: =E21/E3 -> 0.06494295 | F22: =F21/F3 -> 0.07007432 | G22: =G21/G3 -> -0.095315416 | H22: =H21/H3 -> 0.096777806 | I22: =I21/I3 -> 0.043644196 | ... L22: =L21/L3 -> 0.071646912
A23: Average CapEx | L23: =AVERAGE(B22:G22,I22,K22:L22) -> 0.055679525
A24: Change in NWC | B24: ='10K'!B14 -> -4932 | C24: ='10K'!C14 -> -3113 | D24: ='10K'!D14 -> -182 | E24: ='10K'!E14 -> -649 | F24: ='10K'!F14 -> -2566 | G24: ='10K'!G14 -> 923 | H24: ='10K'!H14 -> -1653 | I24: ='10K'!I14 -> 4162 | ... L24: ='10K'!L14 -> -8676 | N24: =N25*N3 -> 2058.561 | O24: =O25*O3 -> 2101.3588 | P24: =P25*P3 -> 2145.0463 | Q24: =Q25*Q3 -> 2189.6421 | R24: =R25*R3 -> 2235.165 | S24: =S25*S3 -> 2281.6343 | T24: =T25*T3 -> 2329.0698 | U24: =U25*U3 -> 2377.4915 | ... X24: =X25*X3 -> 2528.8807
A25: Change in NWC (% of Revenue) | B25: ='10K'!B20 -> 0.0134 | C25: ='10K'!C20 -> 0.013 | D25: ='10K'!D20 -> 0.0009 | E25: ='10K'!E20 -> 0.0027 | F25: ='10K'!F20 -> 0.0092 | G25: ='10K'!G20 -> 0.0036 | H25: ='10K'!H20 -> 0.0093 | I25: ='10K'!I20 -> -0.015 | ... L25: ='10K'!L20 -> 0.0256 | N25: =$L$26 -> 0.0059444444 | O25: =$L$26 -> 0.0059444444 | P25: =$L$26 -> 0.0059444444 | Q25: =$L$26 -> 0.0059444444 | R25: =$L$26 -> 0.0059444444 | S25: =$L$26 -> 0.0059444444 | T25: =$L$26 -> 0.0059444444 | U25: =$L$26 -> 0.0059444444 | ... X25: =$L$26 -> 0.0059444444
A26: Average Change in NWC (without 2020 and 2022) | L26: =AVERAGE(B25:G25,I25,K25:L25) -> 0.0059444444
A27: FCFF | B27: =B13+B18-B21-B24 -> 23022.4 | C27: =C13+C18-C21-C24 -> 11378.75 | D27: =D13+D18-D21-D24 -> 15170.1 | E27: =E13+E18-E21-E24 -> 25571.5 | F27: =F13+F18-F21-F24 -> 23623.11 | G27: =G13+G18-G21-G24 -> 57891.64 | H27: =H13+H18-H21-H24 -> 7922.75 | I27: =I13+I18-I21-I24 -> 28894.96 | ... L27: =L13+L18-L21-L24 -> 43717.68 | N27: =N13+N18-N21-N24 -> 21719.842 | O27: =O13+O18-O21-O24 -> 22171.4 | P27: =P13+P18-P21-P24 -> 22632.346 | Q27: =Q13+Q18-Q21-Q24 -> 23102.875 | R27: =R13+R18-R21-R24 -> 23583.187 | S27: =S13+S18-S21-S24 -> 24073.484 | T27: =T13+T18-T21-T24 -> 24573.975 | U27: =U13+U18-U21-U24 -> 25084.871 | ... X27: =X13+X18-X21-X24 -> 26682.176
A28: PV(FCFF) | N28: =N27/(1+$AA$15)^0 -> 21719.842 | O28: =O27/(1+$AA$15)^1 -> 20960.847 | P28: =P27/(1+$AA$15)^2 -> 20228.376 | Q28: =Q27/(1+$AA$15)^3 -> 19521.5 | R28: =R27/(1+$AA$15)^4 -> 18839.326 | S28: =S27/(1+$AA$15)^5 -> 18180.991 | T28: =T27/(1+$AA$15)^6 -> 17545.66 | U28: =U27/(1+$AA$15)^7 -> 16932.532 | V28: =V27/(1+$AA$15)^8 -> 16340.829 | W28: =W27/(1+$AA$15)^9 -> 15769.802 | X28: =X27/(1+$AA$15)^10 -> 15218.731
A29: Terminal Value | X29: =(X27*(1+AA14))/(AA15-AA14) -> 720890.82
A30: PV(TV) | X30: =X29/(1+AA15)^10 -> 411174.98
A31: Enterprise Value | X31: =SUM(N28:X28,X30) -> 612433.41
A32: Equity Value | X32: =X31-AA3+'Exhibit 4'!B6 -> 593752.41
A33: Intrinsic Price | X33: =X32/'Exhibit 4'!B45 -> 136.40074
